<?xml version="1.0" encoding="utf-8"?>
<!-- This URDF was automatically created by SolidWorks to URDF Exporter! Originally created by Stephen Brawner (brawner@gmail.com) 
     Commit Version: 1.6.0-4-g7f85cfe  Build Version: 1.6.7995.38578
     For more information, please see http://wiki.ros.org/sw_urdf_exporter -->
<robot
  name="allwheel_urdf">
  <link
    name="base_link">
    <inertial>
      <origin
        xyz="3.2612801348364E-15 2.98274859672487E-15 -0.0102615683558075"
        rpy="0 0 0" />
      <mass
        value="0.255742000192013" />
      <inertia
        ixx="0.000302796409258888"
        ixy="-3.92027771042362E-19"
        ixz="-1.46296662392844E-19"
        iyy="0.000302202648247359"
        iyz="-9.95263713023803E-20"
        izz="0.000556226204689963" />
    </inertial>
    <visual>
      <origin
        xyz="0 0 0"
        rpy="0 0 0" />
      <geometry>
        <mesh
          filename="package://allwheel_urdf/meshes/base_link.STL" />
      </geometry>
      <material
        name="">
        <color
          rgba="0.792156862745098 0.819607843137255 0.933333333333333 1" />
      </material>
    </visual>
    <collision>
      <origin
        xyz="0 0 0"
        rpy="0 0 0" />
      <geometry>
        <mesh
          filename="package://allwheel_urdf/meshes/base_link.STL" />
      </geometry>
    </collision>
  </link>
  <link
    name="front_link">
    <inertial>
      <origin
        xyz="0.00291772242218888 -3.96001122382623E-17 3.67729594369733E-17"
        rpy="0 0 0" />
      <mass
        value="0.109903140807102" />
      <inertia
        ixx="2.82980917306225E-05"
        ixy="7.48060042323109E-22"
        ixz="-1.69854388671089E-21"
        iyy="1.73831765621433E-05"
        iyz="8.36445035413622E-21"
        izz="1.73831765621433E-05" />
    </inertial>
    <visual>
      <origin
        xyz="0 0 0"
        rpy="0 0 0" />
      <geometry>
        <mesh
          filename="package://allwheel_urdf/meshes/front_link.STL" />
      </geometry>
      <material
        name="">
        <color
          rgba="0.752941176470588 0.752941176470588 0.752941176470588 1" />
      </material>
    </visual>
    <collision>
      <origin
        xyz="0 0 0"
        rpy="0 0 0" />
      <geometry>
        <mesh
          filename="package://allwheel_urdf/meshes/front_link.STL" />
      </geometry>
    </collision>
  </link>
  <joint
    name="front_wheel_joint"
    type="continuous">
    <origin
      xyz="0.0990025403784439 0 -0.0351150000000006"
      rpy="0 0 0" />
    <parent
      link="base_link" />
    <child
      link="front_link" />
    <axis
      xyz="1 0 0" />
  </joint>
  <link
    name="right_Link">
    <inertial>
      <origin
        xyz="0.00291772242218893 -1.2490009027033E-16 3.36091510237884E-17"
        rpy="0 0 0" />
      <mass
        value="0.109903140807102" />
      <inertia
        ixx="2.82980917306225E-05"
        ixy="3.81164826264435E-21"
        ixz="-2.9926600267234E-21"
        iyy="1.73831765621433E-05"
        iyz="1.01781304777338E-20"
        izz="1.73831765621432E-05" />
    </inertial>
    <visual>
      <origin
        xyz="0 0 0"
        rpy="0 0 0" />
      <geometry>
        <mesh
          filename="package://allwheel_urdf/meshes/right_Link.STL" />
      </geometry>
      <material
        name="">
        <color
          rgba="0.752941176470588 0.752941176470588 0.752941176470588 1" />
      </material>
    </visual>
    <collision>
      <origin
        xyz="0 0 0"
        rpy="0 0 0" />
      <geometry>
        <mesh
          filename="package://allwheel_urdf/meshes/right_Link.STL" />
      </geometry>
    </collision>
  </link>
  <joint
    name="right_wheel_joint"
    type="continuous">
    <origin
      xyz="-0.0495012701892215 -0.0857387150069273 -0.0351150000000006"
      rpy="0 0 -2.09439510239319" />
    <parent
      link="base_link" />
    <child
      link="right_Link" />
    <axis
      xyz="1 0 0" />
  </joint>
  <link
    name="left_Link">
    <inertial>
      <origin
        xyz="0.00291772242218896 -8.32667268468867E-17 4.16322471001811E-17"
        rpy="0 0 0" />
      <mass
        value="0.109903140807102" />
      <inertia
        ixx="2.82980917306225E-05"
        ixy="8.470329472543E-22"
        ixz="-4.04814248834114E-21"
        iyy="1.73831765621433E-05"
        iyz="7.3114989324433E-21"
        izz="1.73831765621432E-05" />
    </inertial>
    <visual>
      <origin
        xyz="0 0 0"
        rpy="0 0 0" />
      <geometry>
        <mesh
          filename="package://allwheel_urdf/meshes/left_Link.STL" />
      </geometry>
      <material
        name="">
        <color
          rgba="0.752941176470588 0.752941176470588 0.752941176470588 1" />
      </material>
    </visual>
    <collision>
      <origin
        xyz="0 0 0"
        rpy="0 0 0" />
      <geometry>
        <mesh
          filename="package://allwheel_urdf/meshes/left_Link.STL" />
      </geometry>
    </collision>
  </link>
  <joint
    name="left_wheel_joint"
    type="continuous">
    <origin
      xyz="-0.049501270189222 0.085738715006927 -0.0351150000000006"
      rpy="0 0 2.0943951023932" />
    <parent
      link="base_link" />
    <child
      link="left_Link" />
    <axis
      xyz="1 0 0" />
  </joint>
  <link
    name="imu_Link">
    <inertial>
      <origin
        xyz="1.38777878078145E-17 -1.64798730217798E-17 0.00117501372111883"
        rpy="0 0 0" />
      <mass
        value="0.0283869958164694" />
      <inertia
        ixx="1.7330818944512E-05"
        ixy="-2.18905765877172E-21"
        ixz="4.09211601360512E-22"
        iyy="2.3993887620163E-05"
        iyz="-1.50877743729675E-21"
        izz="3.82718524716327E-05" />
    </inertial>
    <visual>
      <origin
        xyz="0 0 0"
        rpy="0 0 0" />
      <geometry>
        <mesh
          filename="package://allwheel_urdf/meshes/imu_Link.STL" />
      </geometry>
      <material
        name="">
        <color
          rgba="0.792156862745098 0.819607843137255 0.933333333333333 1" />
      </material>
    </visual>
    <collision>
      <origin
        xyz="0 0 0"
        rpy="0 0 0" />
      <geometry>
        <mesh
          filename="package://allwheel_urdf/meshes/imu_Link.STL" />
      </geometry>
    </collision>
  </link>
  <joint
    name="imu_joint"
    type="fixed">
    <origin
      xyz="0 0 0.032"
      rpy="0 0 0" />
    <parent
      link="base_link" />
    <child
      link="imu_Link" />
    <axis
      xyz="0 0 0" />
  </joint>
</robot>